Workbook

Sheet DISPONIBILITA
A1: QUADRO CONTABILE GENERALE
A3: DISPONIBILITÀ DI SPESA INTESA
A4: =(B74-B76-A20) -> 64.630746
A7: DISPONIBILITÀ DI SPESA FINDOMESTIC
A8: =B72+B73-B77 -> 694
A11: DISPONIBILITÀ DI SPESA CONTANTI
A12: =A51 -> 100
A15: 🌍 DISPONIBILITÀ ACQUISTI ONLINE
A16: =IntesaCC!C20 -> 179
A19: DEPOSITO RISPARMI CC
A20: =10000 -> 10000
A22: TOTALE CAPACITÀ DI SPESA
A23: =A4+A8+A12+A16 -> 1037.6307
A25: =IF(B75>B76,"ATTENZIONE: ALCUNE SPESE PROGRAMMATE SONO STATE RIMANDATE FINO AL PROSSIMO ACCREDITO","")
A31: SALDO CONTI CORRENTI E DEPOSITO
A33: SALDO AGGIORNATO INTESA
A34: =(A45*(-1))+B35 -> 13041 | C34: =A34 -> 13041
A35: saldo prima del giroconto: | B35: =13041 -> 13041
A37: SALDO AGGIORNATO FINDOMESTIC
A38: =(A45)+B39 -> 372 | C38: =A38 -> 372
A39: saldo prima del giroconto: | B39: =372 -> 372
A41: CONTO DEPOSITO FINDOMESTIC
A42: =532 -> 532 | C42: =A42 -> 532
A44: Giroconto da Intesa a Findomestic
A47: CONTANTI A DEPOSITO
A48: =Contanti!C5 -> 2000
A50: CONTANTI LIQUIDITÀ
A51: =Contanti!C6 -> 100
A53: CONTANTI GIACENZA TOTALE
A54: =A48+A51 -> 2100
A58: PATRIMONIO TOTALE CONTABILE
A59: =B74+B72+B73+A54 -> 16045
A60: Somma del patrimonio totale derivante da conti correnti, depositi bancari e contanti
A62: PATRIMONIO A DISPOSIZIONE
A63: =A59-(B75+B77) -> 12858.631
A64: Somma depositi e conti correnti bancari netti delle spese programmate
A66: TOTALE RISPARMI
A67: =A20+A48+A42 -> 12532
A68: Somma totale composta da deposito bancario (deposito risparmi CC Intesa + deposito Findomestic) e deposito contanti
A71: Riepilogo conti e giacenze
...

Sheet IntesaCC
B1: aggiornato al | C1: =NOW() -> 46242.753 | D1: n. | I1: Totale spese rimandabili
B2: Saldo alla data odierna | C2: =spese!C2 -> 13041
B3: Prelievo/Versamento | C3: =C2-C4 -> 10064.631
B4: Totale giacenza necessaria | C4: =SUM(C13:C303) -> 2976.3693
B5: Spese rimandabili | C5: =SUM(I13:I303) -> 0
B6: Saldo alla data odierna | C6: =C2 -> 13041
B7: Prelievo massimo | C7: =C6-C8 -> 10064.631
B8: Giacenza Minima | C8: =(C4-C5) -> 2976.3693
B12: Importi fissi e spese online
A13: FALSE | B13: =IF(spese!A13="i",spese!B13,"") -> Finanziamento Findomestic | C13: =IF(spese!A13="i",spese!C13*D13,"") -> 430 | D13: 1 | I13: =IF(A13=true,C13,"")
A14: FALSE | B14: =IF(spese!A14="i",spese!B14,"") -> Assestamenti (30 gg x 18+3 €) | C14: =IF(spese!A14="i",(spese!C14-(spese!C14/spese!E14)*(spese!E14-spese!F14)),"") -> 189 | I14: =IF(A14=true,C14,"") | J14: =IF(spese!A14="i",spese!C14,"") -> 630
A15: FALSE | B15: =IF(spese!A15="i",spese!B15,"") -> Cellulare Pier | C15: =IF(spese!A15="i",spese!C15,"") -> 10 | I15: =IF(A15=true,C15,"")
A16: FALSE | B16: =IF(spese!A16="i",spese!B16,"") -> Cellulare Simo | C16: =IF(spese!A16="i",spese!C16,"") -> 10 | I16: =IF(A16=true,C16,"")
A17: FALSE | B17: =IF(spese!A17="i",spese!B17,"") -> Cellulare Diletta | C17: =IF(spese!A17="i",spese!C17,"") -> 10 | I17: =IF(A17=true,C17,"")
A18: FALSE | B18: =IF(spese!A18="i",spese!B18,"") -> Netflix | C18: =IF(spese!A18="i",spese!C18,"") -> 10 | I18: =IF(A18=true,C18,"")
A19: FALSE | B19: =IF(spese!A19="i",spese!B19,"") -> Arrampicata Diletta | C19: =IF(spese!A19="i",spese!C19,"") -> 45 | I19: =IF(A19=true,C19,"")
A20: FALSE | B20: =IF(spese!A20="i",spese!B20,"") -> Acquisti vari on-line | C20: =IF(spese!A20="i",spese!C20-Acquisti!B1,"") -> 179 | I20: =IF(A20=true,C20,"")
A21: FALSE | B21: =IF(spese!A21="i",spese!B21,"") | C21: =IF(spese!A21="i",spese!C21,"") | I21: =IF(A21=true,C21,"")
A22: FALSE | B22: =IF(spese!A22="i",spese!B22,"") | C22: =IF(spese!A22="i",spese!C22,"") | I22: =IF(A22=true,C22,"")
A23: FALSE | B23: =IF(spese!A23="i",spese!B23,"") | C23: =IF(spese!A23="i",spese!C23,"") | I23: =IF(A23=true,C23,"")
A24: FALSE | B24: =IF(spese!A24="i",spese!B24,"") | C24: =IF(spese!A24="i",spese!C24,"") | I24: =IF(A24=true,C24,"")
A25: FALSE | B25: =IF(spese!A25="i",spese!B25,"") | C25: =IF(spese!A25="i",spese!C25,"") | I25: =IF(A25=true,C25,"")
A26: FALSE | C26: =IF(spese!A26="i",spese!C26,"") | I26: =IF(A26=true,C26,"")
A27: FALSE | C27: =IF(spese!A27="i",spese!C27,"") | I27: =IF(A27=true,C27,"")
I28: =IF(A28=true,C28,"")
A29: FALSE | B29: =IF(spese!A29="i",spese!B29,"") -> quota assicurazione c3 (scadenza 27/11/2026) | C29: =IF(spese!A29="i",(spese!C29/spese!E29)*(spese!E29-spese!F29),"") -> 318.08219 | I29: =IF(A29=true,C29,"")
A30: FALSE | B30: =IF(spese!A30="i",spese!B30,"") -> quota assicurazione c1 | C30: =IF(spese!A30="i",(spese!C30/spese!E30)*(spese!E30-spese!F30),"") -> 200.68493 | I30: =IF(A30=true,C30,"")
A31: FALSE | B31: =IF(spese!A31="i",spese!B31,"") -> quota bollo c1 | C31: =IF(spese!A31="i",(spese!C31/spese!E31)*(spese!E31-spese!F31),"") -> 114.6411 | I31: =IF(A31=true,C31,"")
A32: FALSE | B32: =IF(spese!A32="i",spese!B32,"") -> quota condominio (trimestre) | C32: =IF(spese!A32="i",(spese!C32/spese!E32)*(spese!E32-spese!F32),"") -> 133.33333 | I32: =IF(A32=true,C32,"")
A33: FALSE | B33: =IF(spese!A33="i",spese!B33,"") -> quota bollo c3 | C33: =IF(spese!A33="i",(spese!C33/spese!E33)*(spese!E33-spese!F33),"") -> 139.8274 | I33: =IF(A33=true,C33,"")
A34: FALSE | B34: =IF(spese!A34="i",spese!B34,"") -> Tari (ott. dic. feb. apr.) | C34: =IF(spese!A34="i",(spese!C34/spese!E34)*(spese!E34-spese!F34),"") -> 48 | I34: =IF(A34=true,C34,"")
A35: FALSE | B35: =IF(spese!A35="i",spese!B35,"") -> Eni luce e gas | C35: =IF(spese!A35="i",(spese!C35/spese!E35)*(spese!E35-spese!F35),"") -> 163.33333 | I35: =IF(A35=true,C35,"")
A36: FALSE | B36: =IF(spese!A36="i",spese!B36,"") -> Abbanoa | C36: =IF(spese!A36="i",(spese!C36/spese!E36)*(spese!E36-spese!F36),"") -> 307.88889 | I36: =IF(A36=true,C36,"")
A37: FALSE | B37: =IF(spese!A37="i",spese!B37,"") -> Tagliando C3 | C37: =IF(spese!A37="i",(spese!C37/spese!E37)*(spese!E37-spese!F37),"") -> 169.36986 | I37: =IF(A37=true,C37,"")
A38: FALSE | B38: =IF(spese!A38="i",spese!B38,"") -> Distribuzione C3 | C38: =IF(spese!A38="i",(spese!C38/spese!E38)*(spese!E38-spese!F38),"") -> 387.0137 | I38: =IF(A38=true,C38,"")
A39: FALSE | B39: =IF(spese!A39="i",spese!B39,"") -> Garanzia Motore C3 | C39: =IF(spese!A39="i",(spese!C39/spese!E39)*(spese!E39-spese!F39),"") -> 76.986301 | I39: =IF(A39=true,C39,"")
A40: FALSE | B40: =IF(spese!A40="i",spese!B40,"") -> PEC Aruba | C40: =IF(spese!A40="i",(spese!C40/spese!E40)*(spese!E40-spese!F40),"") -> 9.3315068 | I40: =IF(A40=true,C40,"")
... A43: FALSE | B43: =IF(spese!A43="i",spese!B43,"") | C43: =IF(spese!A43="i",(spese!C43/spese!E43)*(spese!E43-spese!F43),"") | I43: =IF(A43=true,C43,"")
A44: FALSE | B44: Spese varie (bollette ecc.) | I44: =IF(A44=true,C44,"")
A45: FALSE | B45: =IF(spese!A45="i",spese!B45,"") | C45: =IF(spese!A45="i",spese!C45,"") | I45: =IF(A45=true,C45,"")
...

Sheet FindomesticCC
B1: aggiornato al | C1: =NOW() -> 46242.753 | D1: alert! | I1: Totale spese rimandabili
B2: Saldo alla data odierna | C2: =spese!C3 -> 372
B3: Disponibilità minima | C3: =C2 -> 372
B4: Totale giacenza necessaria | C4: =SUM(C13:C303) -> 210
B5: Spese rimandabili | C5: =SUM(I13:I303) -> 0
B6: Conto Deposito | C6: =spese!C4 -> 532
B7: Disponibilità totale | C7: =C2+C6 -> 904
B8: Giacenza Minima | C8: =(C4-C5) -> 210
B10: DISPONIBILITÀ CONTABILE | C10: =C2+C6-C4 -> 694 | D10: =IF(C8>C7,"🆘","✅") -> ✅
B12: Importi fissi e spese online
B13: =IF(spese!A13="f",spese!B13,"") | C13: =IF(spese!A13="f",spese!C13*D13,"") | I13: =IF(A13="x",C13,"")
B14: =IF(spese!A14="f",spese!B14,"") | C14: =IF(spese!A14="f",spese!C14,"") | I14: =IF(A14="x",C14,"")
B15: =IF(spese!A15="f",spese!B15,"") | C15: =IF(spese!A15="f",spese!C15,"") | I15: =IF(A15="x",C15,"")
B16: =IF(spese!A16="f",spese!B16,"") | C16: =IF(spese!A16="f",spese!C16,"") | I16: =IF(A16="x",C16,"")
B17: =IF(spese!A17="f",spese!B17,"") | C17: =IF(spese!A17="f",spese!C17,"") | I17: =IF(A17="x",C17,"")
B18: =IF(spese!A18="f",spese!B18,"") | C18: =IF(spese!A18="f",spese!C18,"") | I18: =IF(A18="x",C18,"")
B19: =IF(spese!A19="f",spese!B19,"") | C19: =IF(spese!A19="f",spese!C19,"")
B20: =IF(spese!A20="f",spese!B20,"") | C20: =IF(spese!A20="f",spese!C20-Acquisti!B1,"") | I20: =IF(A20="x",C20,"")
B21: =IF(spese!A21="f",spese!B21,"") -> Da versare nel conto di Diletta | C21: =IF(spese!A21="f",spese!C21,"") -> 200
B22: =IF(spese!A22="f",spese!B22,"") | C22: =IF(spese!A22="f",spese!C22,"")
B23: =IF(spese!A23="f",spese!B23,"") | C23: =IF(spese!A23="f",spese!C23,"")
B24: =IF(spese!A24="f",spese!B24,"") | C24: =IF(spese!A24="f",spese!C24,"")
B25: =IF(spese!A25="f",spese!B25,"") | C25: =IF(spese!A25="f",spese!C25,"")
B26: =IF(spese!A26="f",spese!B26,"") | C26: =IF(spese!A26="f",spese!C26,"")
B27: =IF(spese!A27="f",spese!B27,"") -> costi cc bancario Findomestic | C27: =IF(spese!A27="f",spese!C27,"") -> 10
B28: Spese a scadenza programmata
B29: =IF(spese!A29="f",spese!B29,"") | C29: =IF(spese!A29="f",(spese!C29/spese!E29)*(spese!E29-spese!F29),"") | I29: =IF(A29="x",C29,"")
B30: =IF(spese!A30="f",spese!B30,"") | C30: =IF(spese!A30="f",(spese!C30/spese!E30)*(spese!E30-spese!F30),"") | I30: =IF(A30="x",C30,"")
B31: =IF(spese!A31="f",spese!B31,"") | C31: =IF(spese!A31="f",(spese!C31/spese!E31)*(spese!E31-spese!F31),"") | I31: =IF(A31="x",C31,"")
B32: =IF(spese!A32="f",spese!B32,"") | C32: =IF(spese!A32="f",(spese!C32/spese!E32)*(spese!E32-spese!F32),"") | I32: =IF(A32="x",C32,"")
B33: =IF(spese!A33="f",spese!B33,"") | C33: =IF(spese!A33="f",(spese!C33/spese!E33)*(spese!E33-spese!F33),"") | I33: =IF(A33="x",C33,"")
B34: =IF(spese!A34="f",spese!B34,"") | C34: =IF(spese!A34="f",(spese!C34/spese!E34)*(spese!E34-spese!F34),"") | I34: =IF(A34="x",C34,"")
B35: =IF(spese!A35="f",spese!B35,"") | C35: =IF(spese!A35="f",(spese!C35/spese!E35)*(spese!E35-spese!F35),"") | I35: =IF(A35="x",C35,"")
B36: =IF(spese!A36="f",spese!B36,"") | C36: =IF(spese!A36="f",(spese!C36/spese!E36)*(spese!E36-spese!F36),"") | I36: =IF(A36="x",C36,"")
B37: =IF(spese!A37="f",spese!B37,"") | C37: =IF(spese!A37="f",(spese!C37/spese!E37)*(spese!E37-spese!F37),"") | I37: =IF(A37="x",C37,"")
B38: =IF(spese!A38="f",spese!B38,"") | C38: =IF(spese!A38="f",(spese!C38/spese!E38)*(spese!E38-spese!F38),"") | I38: =IF(A38="x",C38,"")
B39: =IF(spese!A39="f",spese!B39,"") | C39: =IF(spese!A39="f",(spese!C39/spese!E39)*(spese!E39-spese!F39),"") | I39: =IF(A39="x",C39,"")
B40: =IF(spese!A40="f",spese!B40,"") | C40: =IF(spese!A40="f",(spese!C40/spese!E40)*(spese!E40-spese!F40),"") | I40: =IF(A40="x",C40,"")
... B43: =IF(spese!A43="f",spese!B43,"") | C43: =IF(spese!A43="f",(spese!C43/spese!E43)*(spese!E43-spese!F43),"") | I43: =IF(A43="x",C43,"")
B44: Spese varie (bollette ecc.) | I44: =IF(A44="x",C44,"")
...

Sheet spese
B1: IMPORTI SPESE FISSE, ACQUISTI ONLINE E VARIE | D1: Scadenza | E1: Periodo (giorni) | F1: Giorni mancanti
A2: I | B2: Saldo INTESA | C2: =DISPONIBILITA!C34 -> 13041
A3: F | B3: Saldo FINDOMESTIC | C3: =DISPONIBILITA!C38 -> 372
A4: F | B4: CONTO DEPOSITO Findomestic | C4: =DISPONIBILITA!C42 -> 532
B5: TOTALE GIACENZA | C5: =C2+C3+C4 -> 13945
B6: Totale spese fisse, programmate e varie | C6: =(IntesaCC!C4+FindomesticCC!C4) -> 3186.3693
B7: Possibile prelievo/versamento da Intesa | C7: =IntesaCC!C3 -> 10064.631
B8: CC Intesa dopo prelievo/versamento | C8: =C2-C7 -> 2976.3693
B9: CC Findomestic dopo prelievo/versamento | C9: =C3+C7 -> 10436.631
B10: Accrediti in programma
B11: Giacenza dopo eventuali accrediti | C11: =C5+C10 -> 13945
B12: Importi fissi e spese online
A13: i | B13: Finanziamento Findomestic | C13: 430
A14: i | B14: Assestamenti (30 gg x 18+3 €) | C14: =30*(18+3) -> 630 | D14: 46251 | E14: 30 | F14: =IF(D14>0,DATEDIF(IntesaCC!$C$1,D14,"D"),"") -> 9
A15: i | B15: Cellulare Pier | C15: 10
A16: i | B16: Cellulare Simo | C16: 10
A17: i | B17: Cellulare Diletta | C17: 10
A18: i | B18: Netflix | C18: 10
A19: i | B19: Arrampicata Diletta | C19: 45
A20: i | B20: Acquisti vari on-line | C20: 250
A21: f | B21: Da versare nel conto di Diletta | C21: =(contodiletta!C101) -> 200
A27: f | B27: costi cc bancario Findomestic | C27: 10
B28: Spese a scadenza programmata
A29: i | B29: quota assicurazione c3 (scadenza 27/11/2026) | C29: 450 | D29: 46349 | E29: 365 | F29: =IF(D29>0,DATEDIF(IntesaCC!$C$1,D29,"D"),"") -> 107
A30: i | B30: quota assicurazione c1 | C30: 250 | D30: 46314 | E30: 365 | F30: =IF(D30>0,DATEDIF(IntesaCC!$C$1,D30,"D"),"") -> 72
A31: i | B31: quota bollo c1 | C31: 132 | D31: 46290 | E31: 365 | F31: =IF(D31>0,DATEDIF(IntesaCC!$C$1,D31,"D"),"") -> 48
A32: i | B32: quota condominio (trimestre) | C32: 150 | D32: 46252 | E32: 90 | F32: =IF(D32>0,DATEDIF(IntesaCC!$C$1,D32,"D"),"") -> 10
A33: i | B33: quota bollo c3 | C33: 161 | D33: 46290 | E33: 365 | F33: =IF(D33>0,DATEDIF(IntesaCC!$C$1,D33,"D"),"") -> 48
A34: i | B34: Tari (ott. dic. feb. apr.) | C34: 90 | D34: 46326 | E34: 180 | F34: =IF(D34>0,DATEDIF(IntesaCC!$C$1,D34,"D"),"") -> 84 | G34: dopo il saldo: 180 GG. Tra le rate: 60 gg
A35: i | B35: Eni luce e gas | C35: 350 | D35: 46274 | E35: 60 | F35: =IF(D35>0,DATEDIF(IntesaCC!$C$1,D35,"D"),"") -> 32
A36: i | B36: Abbanoa | C36: 326 | D36: 46247 | E36: 90 | F36: =IF(D36>0,DATEDIF(IntesaCC!$C$1,D36,"D"),"") -> 5
A37: i | B37: Tagliando C3 | C37: 220 | D37: 46326 | E37: 365 | F37: =IF(D37>0,DATEDIF(IntesaCC!$C$1,D37,"D"),"") -> 84
A38: i | B38: Distribuzione C3 | C38: 700 | D38: 47058 | E38: 1825 | F38: =IF(D38>0,DATEDIF(IntesaCC!$C$1,D38,"D"),"") -> 816
A39: i | B39: Garanzia Motore C3 | C39: 100 | D39: 46326 | E39: 365 | F39: =IF(D39>0,DATEDIF(IntesaCC!$C$1,D39,"D"),"") -> 84
A40: i | B40: PEC Aruba | C40: 13 | D40: 46345 | E40: 365 | F40: =IF(D40>0,DATEDIF(IntesaCC!$C$1,D40,"D"),"") -> 103
A41: i | B41: Revisione C1 | C41: 80 | D41: 46996 | E41: =365*2 -> 730 | F41: =IF(D41>0,DATEDIF(IntesaCC!$C$1,D41,"D"),"") -> 754
A42: i | B42: Revisione C3 | C42: 80 | D42: 46721 | E42: =365*2 -> 730 | F42: =IF(D42>0,DATEDIF(IntesaCC!$C$1,D42,"D"),"") -> 479
F43: =IF(D43>0,DATEDIF(IntesaCC!$C$1,D43,"D"),"")
B44: Spese varie (bollette ecc.)
F45: =IF(D45>0,DATEDIF(IntesaCC!$C$1,D45,"M"),"")

Sheet Acquisti
A1: Acquisti on-line | B1: =SUM(B3:B300) -> 71
A2: Descrizione | B2: Importo
A3: shein | B3: 50
A4: temu | B4: 21

Sheet Note
A1: Movimento | B1: Data | C1: Importo
A2: Quattordicesima Pier 2021 | B2: 44407 | C2: 89
A3: Tredicesima Pier 2021 | B3: 44551 | C3: 614
A4: Quattordicesima Pier 2022 | B4: 44778 | C4: 1047
A5: Tredicesima Pier 2022 | B5: 44922 | C5: 1052
A6: Quattordicesima Pier 2023 | B6: 45133 | C6: 1069
A7: Tredicesima Pier 2023 | B7: 45281 | C7: 1068
A8: Quattordicesima Pier 2024 | B8: 45492 | C8: 1116
A9: Tredicesima Pier 2024 | B9: 45645 | C9: 1129
A10: Stipendio Giugno 25 | B10: 45855 | C10: 1500
A11: Quattordicesima Pier 2025 | B11: 45870 | C11: 1148
A12: stipendio luglio 25 | B12: 45882 | C12: 1864
A13: stipendio agosto 25 | B13: 45917 | C13: 1524
... A25: Quattordicesima Pier 2026 | B25: 46241 | C25: 1190

Sheet versamento
A1: Totale versamento su CC Findomestic | D1: =SUM(D5:D303)-(D2+D3) -> -904
A2: Giacenza Findo | D2: =DISPONIBILITA!C38 -> 372
A3: Conto deposito | D3: =DISPONIBILITA!C42 -> 532
A4: Descrizione | D4: Importo
A5: FALSE | B5: Benzina C1 | C5: =20*4 -> 80 | D5: =IF(A5=TRUE,C5,"")
A6: FALSE | B6: Benzina C3 | C6: =20*4 -> 80 | D6: =IF(A6=TRUE,C6,"")
A7: FALSE | B7: Liquidi | C7: =21*4 -> 84 | D7: =IF(A7=TRUE,C7,"")
A8: FALSE | B8: Laser Diletta | C8: 120 | D8: =IF(A8=TRUE,C8,"")
A9: FALSE | B9: Caffè | C9: =1.4*22 -> 30.8 | D9: =IF(A9=TRUE,C9,"")
A10: FALSE | B10: Spese conto corrente | C10: 5 | D10: =IF(A10=TRUE,C10,"")
A11: FALSE | B11: Parrucchiera Simona | C11: 50 | D11: =IF(A11=TRUE,C11,"")
A12: FALSE | B12: Barbiere Pier | C12: 15 | D12: =IF(A12=TRUE,C12,"")
A13: FALSE | B13: Condominio | C13: 150 | D13: =IF(A13=TRUE,C13,"")
A14: FALSE | B14: Spese varie | C14: 150 | D14: =IF(A14=TRUE,C14,"")
A15: FALSE | B15: Regalo Diletta Natale | C15: 100 | D15: =IF(A15=TRUE,C15,"")
A16: FALSE | D16: =IF(A16=TRUE,C16,"")
A17: FALSE | D17: =IF(A17=TRUE,C17,"")
A18: FALSE | D18: =IF(A18=TRUE,C18,"")
A19: FALSE | D19: =IF(A19=TRUE,C19,"")
A20: FALSE | D20: =IF(A20=TRUE,C20,"")
A21: FALSE | D21: =IF(A21=TRUE,C21,"")
A22: FALSE | D22: =IF(A22=TRUE,C22,"")
A23: FALSE | D23: =IF(A23=TRUE,C23,"")
A24: FALSE | D24: =IF(A24=TRUE,C24,"")
A25: FALSE | D25: =IF(A25=TRUE,C25,"")
A26: FALSE | D26: =IF(A26=TRUE,C26,"")
A27: FALSE | D27: =IF(A27=TRUE,C27,"")
... A35: FALSE | D35: =IF(A35=TRUE,C35,"")

Sheet contodiletta
A1: TOTALE RISPARMI DILETTA
A2: =C7+C9 -> 377
A3: Importo totale dei risparmi, considerati i soldi in contanti conservati, il residuo su carta , gli importi prelevati da mamma e papà da restituire tramite ricariche su carta o contanti e le eventuali entrate su conti diversi da versare su carta con ricarica se non ancora fatto (es. bonus, regali, rimborsi, borse di studio ecc.).
A4: COMPOSTI DA:
A5: Disponibilità Attuale Contante | C5: =C13-C18-C9 -> 0
A6: Disponibilità Attuale Carta Flash | C6: =C14-C19 -> 177
A7: TOTALE DISPONIBILITÀ ATTUALE | C7: =C5+C6 -> 177
A8: +
A9: TOTALE ANCORA DA VERSARE | C9: =C101 -> 200
A10: Importi prelevati dai contanti da mamma e papà per acquisti in contanti (da restituire in contanti o. con ricarica) o per versare sulla carta Flash tramite ricarica
A12: QUADRO CONTABILE
A13: ENTRATE IN CONTANTI | C13: =C27 -> 750
A14: ENTRATE CARTA FLASH | C14: =C102+C41 -> 911
A15: TOTALE ENTRATE DILETTA | C15: =C13+C14 -> 1661
A16: Somma delle entrate materialmente già percepite
A17: -
A18: SPESE PERSONALI IN CONTANTI | C18: =C57 -> 550
A19: SPESE PERSONALI CON CARTA FLASH | C19: =C78 -> 734
A20: TOTALE USCITE DILETTA | C20: =C18+C19 -> 1284
A21: Totale degli acquisti e delle spese eseguite con carta e in contanti
A23: TOTALE DISPONIBILITÀ CONTABILE | C23: =C15-C20 -> 377
A26: ENTRATE
A27: TOTALE ENTRATE IN CONTANTI | C27: =SUM(C29:C39) -> 750
A28: Descrizione | C28: Importo
A29: Contanti da regali di Natale | C29: 550
A30: Contanti regalo zia Lore | C30: 50
A31: Contanti regalo Pasqua nonni | C31: 100
A32: regalo nonna Antonella promozione | C32: 50
A41: ACCREDITI ESTERNIB CARTA FLASH | C41: =SUM(C43:C53) -> 0
A42: Descrizione | C42: Importo
A56: USCITE
A57: SPESE PERSONALI IN CONTANTI | C57: =SUM(C59:C76) -> 550
A58: Acquisti in contanti | B58: Data | C58: Importo
A59: spese varie | C59: 100
A60: spese varie | C60: 150
A61: spese varie | C61: 120
A62: spese varie | C62: 180
A78: SPESE PERSONALI CON CARTA | C78: =SUM(C80:C97) -> 734
A79: Pagamenti con carta Flash | B79: Data | C79: Importo
A80: Spese varie | C80: =384-18.3 -> 365.7
...

Sheet Contanti
A1: GESTIONE CONTANTI
A2: =C7 -> 2100
A4: COMPOSTI DA:
A5: Disponibilità Deposito Contante | C5: =C89 -> 2000
A6: Disponibilità Liquidità contanti | C6: =C11 -> 100
A7: TOTALE DISPONIBILITÀ ATTUALE | C7: =C5+C6 -> 2100
A10: MOVIMENTI IN CONTANTI
A11: CONTABILITÀ ENTRATE / USCITE | C11: =B12-C12 -> 100
A12: Parziali | B12: =SUM(B14:B85) -> 3000 | C12: =SUM(C14:C85) -> 2900
A13: Descrizione operazioni | B13: Entrate | C13: Uscite
A14: Giroconto da deposito 22/5/26 | B14: 1000
A15: Prelievo per liquidità | C15: 300
A16: prelievo per liquidità 24/5/26 | C16: 200
A17: prelievo per liquidità | C17: 500
A18: giroconto 13/6/26 | B18: 1000
A19: prelievo per liquidità | C19: 250
A20: prelievo per liquidità | C20: 100
A21: prelievo | C21: 50
A22: prelievo per spesa | C22: 200
A23: spese varie | C23: 500
A24: giroconto 24/7/26 | B24: 1000
A25: spese varie | C25: 800
A88: RISPARMI IN CONTANTI
A89: CONTABILITÀ ENTRATE / USCITE | C89: =B90-C90 -> 2000
A90: Parziali | B90: =SUM(B92:B968) -> 5300 | C90: =SUM(C92:C968) -> 3300
A91: Descrizione operazioni | B91: Entrate | C91: Uscite
A92: Entrata contanti 19/05/26 | B92: 5000
A93: prelievo per liquidità 22/5/26 | C93: 1000
A94: regalo mamma e papà 23/5 | B94: 300
A95: prelievo 7/6/26 | C95: 300
A96: prelievo 13/6/26 | C96: 1000
A97: prelievo 24 7 26 | C97: 1000
